Workbook

Sheet Income_Statement_Data
A1: Particulars | B1: Mar-20 | C1: Mar-21 | D1: Mar-22 | E1: Mar-23 | F1: Mar-24 | G1: Mar-25
A2: Total income | B2: 78211.38 | C2: 78217.13 | D2: 85030.89 | E2: 105788.58 | F2: 134866.89 | G2: 152144.97
A3: Income from financial services | B3: 76339.62 | C3: 76643.88 | D3: 82114.17 | E3: 101390.28 | F3: 131397.89 | G3: 147394.25
A4: Fee based financial services income | B4: 9691.94 | C4: 9358.91 | D4: 11358.62 | E4: 14088.88 | F4: 18256.4 | G4: 20545.08
A5: Brokerage and financial service fees | B5: 9691.94 | C5: 9358.91 | D5: 11358.62 | E5: 14088.88 | F5: 18256.4 | G5: 20545.08
A6: Fund based financial services income | B6: 66647.68 | C6: 67284.97 | D6: 70755.55 | E6: 87301.4 | F6: 113141.49 | G6: 126849.17
A7: Interest income | B7: 62635.16 | C7: 63346.23 | D7: 67376.82 | E7: 85163.77 | F7: 109368.63 | G7: 122677.05
A8: Interest on advances made by banks | B8: 48302.97 | C8: 47619.8 | D8: 49616.58 | E8: 64553.81 | F8: 87106.6 | G8: 97200.27
A9: Interest earned by banks from RBI & banks | B9: 1095.26 | C9: 1037.88 | D9: 1528.15 | E9: 899.01 | F9: 908.27 | G9: 1236.22
A10: Interest earned by banks on investments | B10: 11246.03 | C10: 12558.21 | D10: 14618.91 | E10: 18178.73 | F10: 20010.62 | G10: 22928.35
A11: Interest from other sources earned by banks | B11: 1990.9 | C11: 2130.34 | D11: 1613.18 | E11: 1532.22 | F11: 1343.14 | G11: 1312.21
A12: Dividends | B12: 240.26 | C12: 58.35 | D12: 88.65 | E12: 15 | F12: 41.38 | G12: 24.58
A13: Profit on securitisation of assets and loans | B13: 25.5
A14: Income from treasury operations | B14: 3746.76 | C14: 3880.39 | D14: 3290.08 | E14: 2122.63 | F14: 3731.48 | G14: 4147.54
A15: Gain on securities transactions, sale of invest | B15: 2172.3 | C15: 2302.33 | D15: 1377.7 | E15: 320.54 | F15: 1796.01 | G15: 1984.76
A16: Profit on revaluation of investments | D16: 264.48 | F16: 431.34 | G16: 700.51
A17: Gain relating to forex transactions | B17: 1574.46 | C17: 1578.06 | D17: 1912.38 | E17: 1802.09 | F17: 1935.47 | G17: 2162.78
A18: Other income | B18: 283.6 | C18: 301.88 | D18: 488.07 | E18: 519.26 | F18: 416.42 | G18: 549.31
A19: Prior period and extraordinary income | B19: 1588.16 | C19: 1271.37 | D19: 2428.65 | E19: 3879.04 | F19: 3052.58 | G19: 4201.41
A20: Prior period income | B20: 1588.16 | C20: 1271.37 | D20: 2428.65 | E20: 3879.04 | F20: 3052.58 | G20: 4201.41
A21: Bad debts recovered | B21: 1552.99 | C21: 1245.52 | D21: 2366.83 | E21: 2884.97 | F21: 2772.57 | G21: 3809.31
A22: Provisions written back | B22: 35.17 | C22: 25.85 | D22: 61.82 | E22: 994.07 | F22: 280.01 | G22: 392.1
A25: Particulars | B25: Mar-20 | C25: Mar-21 | D25: Mar-22 | E25: Mar-23 | F25: Mar-24 | G25: Mar-25
A26: Total expenses | B26: 76584.16 | C26: 71628.63 | D26: 72005.41 | E26: 96208.9 | F26: 110005.46 | G26: 125771.49
A27: Operating expenses | B27: 54105.62 | C27: 53801.77 | D27: 56846.98 | E27: 69017.64 | F27: 93353.69 | G27: 104130.04
A28: Financial service expenses | B28: 37564.95 | C28: 36374.78 | D28: 34244.61 | E28: 42813.59 | F28: 59474.16 | G28: 68329.22
A29: Fund based financial services expenses | B29: 37564.95 | C29: 36374.78 | D29: 34244.61 | E29: 42813.59 | F29: 59474.16 | G29: 68329.22
A30: Interest expenses | B30: 37428.96 | C30: 34107.11 | D30: 34244.61 | E30: 42218.02 | F30: 59474.16 | G30: 68329.22
A31: Treasury operations expenses | B31: 135.99 | C31: 2267.67 | E31: 595.57
A32: Loss on securities trans & on sale of invest | C32: 1329.08 | E32: 595.57
A33: Loss on revaluation of investments | C33: 1329.08 | E33: 595.57
A34: Compensation to employees | B34: 5329.99 | C34: 6164.01 | D34: 7612.55 | E34: 8760.05 | F34: 10933.11 | G34: 12192.79
A35: Rent & lease rent | B35: 1136.19 | C35: 1168.27 | D35: 1335.55 | E35: 1435.4 | F35: 1783.61 | G35: 2011.86
A36: Repairs & maintenance | B36: 1142.91 | C36: 1193.7 | D36: 1377.43 | E36: 1481.44 | F36: 1799.33 | G36: 2167.84
A37: Insurance premium paid | B37: 751.1 | C37: 999.43 | D37: 1284.24 | E37: 1418.16 | F37: 1598.58 | G37: 1786.3
A38: Outsourced professional jobs | B38: 125.54 | C38: 126.49 | D38: 210.52 | E38: 177.13 | F38: 192.94 | G38: 212.14
A39: Non-executive directors' fees | B39: 2.07 | C39: 2.49 | D39: 4.99 | E39: 5.55 | F39: 5.59 | G39: 6.25
A40: Advertising expenses | B40: 112.56 | C40: 81.31 | D40: 73.26 | E40: 144.23 | F40: 108.28 | G40: 121.98
A41: Communications expenses | B41: 273.95 | C41: 300.45 | D41: 287.98 | E41: 362.8 | F41: 415.04 | G41: 429.17
A42: Printing & stationery expenses | B42: 162.92 | C42: 169.33 | D42: 230.19 | E42: 312.7 | F42: 353.83 | G42: 370.54
...

Sheet Balance_Sheet_Data
A1: Particulars | B1: Mar-20 | C1: Mar-21 | D1: Mar-22 | E1: Mar-23 | F1: Mar-24 | G1: Mar-25
A2: Total liabilities | B2: 915222.36 | C2: 996160.46 | D2: 1175625.2 | E2: 1317743.9 | F2: 1477892.9 | G2: 1611217.9
A3: Total Capital | B3: 564.34 | C3: 612.75 | D3: 613.95 | E3: 615.37 | F3: 617.31 | G3: 619.47
A4: Paid up equity capital | B4: 564.34 | C4: 612.75 | D4: 613.95 | E4: 615.37 | F4: 617.31 | G4: 619.47
A5: Reserves and funds | B5: 84383.5 | C5: 100990.26 | D5: 114560.11 | E5: 124801.28 | F5: 150444.27 | G5: 179105.65
A6: Free reserves | B6: 26544.76 | C6: 30339.59 | D6: 38454.97 | E6: 44500.85 | F6: 60612.18 | G6: 80064.24
A7: General reserves | B7: 354.31 | C7: 354.31 | D7: 354.31 | E7: 355.92 | F7: 358.12 | G7: 1826.24
A8: Balance as per profit & loss account | B8: 26190.45 | C8: 29985.28 | D8: 38100.66 | E8: 44144.93 | F8: 60254.06 | G8: 78238
A9: Specific reserves | B9: 57838.74 | C9: 70650.67 | D9: 76105.14 | E9: 80300.43 | F9: 89832.09 | G9: 99041.41
A10: Security premium reserves (net of deductions) | B10: 41138.2 | C10: 51229.39 | D10: 51505.24 | E10: 51893.22 | F10: 52497.46 | G10: 53315.56
A11: Capital reserves (incl grants and subsidies) | B11: 2432.91 | C11: 3281.15 | D11: 3722.19 | E11: 3790.03 | F11: 3929.58 | G11: 4143.93
A12: Deposits (accepted by commercial banks) | B12: 640104.94 | C12: 707306.08 | D12: 821971.55 | E12: 946945.2 | F12: 1068641.4 | G12: 1172952
A13: Demand deposits | B13: 90114.44 | C13: 113276.17 | D13: 127556.78 | E13: 149120.49 | F13: 157268.02 | G13: 166798.68
... A16: Borrowings | B16: 147954.13 | C16: 142873.16 | D16: 185133.86 | E16: 186300.05 | F16: 196811.75 | G16: 184146.51
A17: From banks | B17: 50 | C17: 35.5 | E17: 5 | F17: 5 | G17: 720.17
A18: From financial institutions | B18: 56319.21 | C18: 60222.56 | D18: 95064.68 | E18: 117433.27 | F18: 137149.16 | G18: 126388.68
A19: Debentures and bonds | B19: 7000 | C19: 7000 | D19: 3500
A20: Foreign currency borrowings | B20: 55460.92 | C20: 40008.1 | D20: 54387.18 | E20: 37512.78 | F20: 36077.59 | G20: 34307.66
A21: Sub-ordinated debt | B21: 17505 | C21: 17505 | D21: 14080 | E21: 23580 | F21: 23580 | G21: 22730
A22: Borrowings from rbi | B22: 11619 | C22: 18102 | D22: 18102 | E22: 7769
A23: Deferred tax liability | B23: 57.54 | C23: 42.04 | D23: 196.48 | E23: 418.33 | F23: 684.31 | G23: 1288.06
A24: Current liabilities & provisions | B24: 42157.91 | C24: 44336.17 | D24: 53149.29 | E24: 58663.62 | F24: 60693.87 | G24: 73106.21
A25: Current liabilities | B25: 34451.42 | C25: 33887.64 | D25: 45506.19 | E25: 49907.62 | F25: 54533.45 | G25: 65585.21
A26: Provisions outstanding | B26: 7706.49 | C26: 10448.53 | D26: 7643.1 | E26: 8756 | F26: 6160.42 | G26: 7521
A27: Total assets | B27: 915222.36 | C27: 996160.46 | D27: 1175625.2 | E27: 1317743.9 | F27: 1477892.9 | G27: 1611217.9
A28: Net fixed assets | B28: 3838.59 | C28: 4135.33 | D28: 4363.22 | E28: 4597.4 | F28: 5442.23 | G28: 6190.51
A29: Intangible assets, net | B29: 530.85 | C29: 702.52 | D29: 981.89 | E29: 1119.95 | F29: 1323.42 | G29: 1774.75
A30: Land and buildings, net | B30: 1646.02 | C30: 1618.19 | D30: 1624.63 | E30: 1597.13 | F30: 1717.95 | G30: 1689.75
A31: Capital work-in-progress | B31: 474.31 | C31: 109.7 | D31: 209.13 | E31: 136.45 | F31: 242.35 | G31: 101.19
A32: Investments | B32: 156734.31 | C32: 226119.62 | D32: 275597.21 | E32: 288814.83 | F32: 331527.24 | G32: 396141.8
A33: Investment in equity shares | B33: 3448.06 | C33: 3513.05 | D33: 4306.92 | E33: 4712.59 | F33: 4960.95 | G33: 9065.45
A34: Investment in debt instruments | B34: 146534.46 | C34: 218921.26 | D34: 269667.74 | E34: 282518.46 | F34: 321670.12 | G34: 381034.89
... A43: Total outside liabilities | B43: 190169.58 | C43: 187251.37 | D43: 238479.63 | E43: 245382 | F43: 258189.93 | G43: 258540.78
A46: Particulars | B46: Mar-20 | C46: Mar-21 | D46: Mar-22 | E46: Mar-23 | F46: Mar-24 | G46: Mar-25
A47: Net fixed assets | B47: 3838.59 | C47: 4135.33 | D47: 4363.22 | E47: 4597.4 | F47: 5442.23 | G47: 6190.51
A48: Intangible assets | B48: 530.85 | C48: 702.52 | D48: 981.89 | E48: 1119.95 | F48: 1323.42 | G48: 1774.75
A49: Buildings | B49: 1646.02 | C49: 1618.19 | D49: 1624.63 | E49: 1597.13 | F49: 1717.95 | G49: 1689.75
A50: Furniture, social amenities & other fixed assets | B50: 1661.72 | C50: 1814.62 | D50: 1756.7 | E50: 1880.32 | F50: 2400.86 | G50: 2726.01
A51: Capital work-in-progress | B51: 474.31 | C51: 109.7 | D51: 209.13 | E51: 136.45 | F51: 242.35 | G51: 101.19
A52: Investments | B52: 156734.31 | C52: 226119.62 | D52: 275597.21 | E52: 288814.83 | F52: 331527.24 | G52: 396141.8
...

Sheet Market_Data
A1: Announcement date | B1: Dividend rate | C1: Dividend per share | D1: Dividend type | E1: Record date | F1: BSE | G1: BSE2 | H1: NSE | I1: NSE3
B2: (%) | F2: Ex-date | G2: Closing price | H2: Ex-date | I2: Closing price
A3: 45771 | B3: 50 | C3: 1 | D3: Final | E3: 45842 | F3: 45842 | G3: 1177.55 | H3: 45842 | I3: 1177.6
A4: 45406 | B4: 50 | C4: 1 | D4: Final | E4: 45485 | F4: 45485 | G4: 1317.8 | H4: 45485 | I4: 1317.3
A5: 45043 | B5: 50 | C5: 1 | D5: Final | E5: 45114 | F5: 45114 | G5: 978.7 | H5: 45114 | I5: 976.7
A6: 44679 | B6: 50 | C6: 1 | D6: Final | E6: 44750 | F6: 44749 | G6: 658.45 | H6: 44749 | I6: 658.15
A7: 43580 | B7: 50 | C7: 1 | D7: Final | E7: 43652 | F7: 43650 | G7: 808.65 | H7: 43650 | I7: 808.85
A8: 42851 | B8: 250 | C8: 5 | D8: Final | E8: 42924 | F8: 42922 | G8: 509.65 | H8: 42922 | I8: 509.5
A9: 42486 | B9: 250 | C9: 5 | D9: Final | E9: 42560 | F9: 42558 | G9: 542.45 | H9: 42558 | I9: 542.25
A10: 42123 | B10: 230 | C10: 4.6 | D10: Final | E10: 42198 | F10: 42194 | G10: 571.8 | H10: 42194 | I10: 571.7
A11: 41754 | B11: 200 | C11: 20 | D11: Final | E11: 41806 | F11: 41802 | G11: 1904.5 | H11: 41802 | I11: 1902.75
A12: 41389 | B12: 180 | C12: 18 | D12: Final | E12: 41464 | F12: 41460 | G12: 1284.7 | H12: 41460 | I12: 1288.05
A13: 41026 | B13: 160 | C13: 16 | D13: Final | E13: 41076 | F13: 41074 | G13: 1012.35 | H13: 41074 | I13: 1013.05
A14: 40655 | B14: 140 | C14: 14 | D14: Final | E14: 40704 | F14: 40702 | G14: 1228.45 | H14: 40702 | I14: 1228.75
... A26: 36309 | B26: 10 | C26: 1 | D26: Final | E26: 36355 | F26: 36318 | G26: 15.5 | H26: 36320 | I26: 15.25

Sheet Ratios_Data
A1: Particulars | B1: Mar-20 | C1: Mar-21 | D1: Mar-22 | E1: Mar-23 | F1: Mar-24 | G1: Mar-25
A2: EPS basic | B2: 5.99 | C2: 22.15 | D2: 42.48 | E2: 31.17 | F2: 80.67 | G2: 85.28
A3: EPS diluted | B3: 5.97 | C3: 22.09 | D3: 42.35 | E3: 31.02 | F3: 80.1 | G3: 84.77
A4: Nominal value of shares (Rs.) | B4: 2 | C4: 2 | D4: 2 | E4: 2 | F4: 2 | G4: 2
A5: Potential addn to eq shares on stock options | B5: 8395776 | C5: 7886586 | D5: 9200000 | E5: 14800000 | F5: 22300000 | G5: 18400000
A6: Potential addn to eq shares due to other sources | B6: 1420559
A9: Particulars | B9: Mar-20 | C9: Mar-21 | D9: Mar-22 | E9: Mar-23 | F9: Mar-24 | G9: Mar-25
A10: Price / EPS (PE)(times) | B10: 2458.11 | C10: 40.14 | D10: 22.04 | E10: 46.28 | F10: 39.79 | G10: 14.63
A11: Earnings per share (EPS)(Indian Rupee) | B11: 0.15 | C11: 17.38 | D11: 34.54 | E11: 18.55 | F11: 26.34 | G11: 75.34
A12: Cash earnings per share (CPS)(Indian Rupee) | B12: 2.91 | C12: 20.48 | D12: 37.83 | E12: 61.12 | F12: 68.77 | G12: 79.66
A13: Price / book value (PB)(times) | B13: 1.26 | C13: 2.1 | D13: 2.03 | E13: 2.11 | F13: 2.27 | G13: 2.01
A14: Book value per share (Indian Rupee) | B14: 301.05 | C14: 331.63 | D14: 375.19 | E14: 407.61 | F14: 462.79 | G14: 548.89
A15: Adjusted closing price (Indian Rupee) | B15: 379.3 | C15: 697.5 | D15: 761.15 | E15: 858.5 | F15: 1048.3 | G15: 1102
A16: Yield (%) | B16: 0.26 | C16: 0 | D16: 0 | E16: 0.12 | F16: 0.1 | G16: 0.09
A17: Equity dividend / Net worth (%) | B17: 0.34 | C17: 0 | D17: 0 | E17: 0.24 | F17: 0.22 | G17: 0.18
A18: Equity dividend / PAT (times) | B18: 0.18 | E18: 0.03 | F18: 0.01 | G18: 0.01
A19: Dividend cover (times) | B19: 5.63 | E19: 31.19 | F19: 80.72 | G19: 85.33
A20: RONW (%) | B20: 0.06 | C20: 5.71 | D20: 9.78 | E20: 4.74 | F20: 15.78 | G20: 13.41
A21: ROCE (%) | B21: 0.02 | C21: 2.23 | D21: 3.89 | E21: 1.87 | F21: 6.61 | G21: 6.23
A22: ROTA (%) | B22: 0.01 | C22: 0.56 | D22: 0.98 | E22: 0.46 | F22: 1.56 | G22: 1.44
A23: Enterprise value | B23: 157712.09 | C23: 294839.81 | D23: 307800.59 | E23: 344037 | F23: 405922.54 | G23: 425744.5
A24: Market capitalisation / enterprise value (times) | B24: 0.68 | C24: 0.72 | D24: 0.76 | E24: 0.77 | F24: 0.8 | G24: 0.8
A25: Enterprise value / PBDITA (times) | B25: 2.56 | C25: 4.85 | D25: 4.93 | E25: 4.32 | F25: 4.02 | G25: 3.66
A26: Market capitalisation | B26: 107026.24 | C26: 213696.47 | D26: 233653.86 | E26: 264147.75 | F26: 323565.17 | G26: 341330.07
A27: Preference capital
A28: Cash & cash equivalents (less) | B28: 97268.28 | C28: 61729.82 | D28: 110987.13 | E28: 106410.8 | F28: 114454.38 | G28: 99732.08
A29: Borrowings | B29: 147954.13 | C29: 142873.16 | D29: 185133.86 | E29: 186300.05 | F29: 196811.75 | G29: 184146.51
A30: Debt equity ratio (times) | B30: 1.74 | C30: 1.41 | D30: 1.61 | E30: 1.49 | F30: 1.3 | G30: 1.02
A31: Equity capital | B31: 564.34 | C31: 612.75 | D31: 613.95 | E31: 615.37 | F31: 617.31 | G31: 619.47
A32: Net worth (book value) | B32: 84947.83 | C32: 101603 | D32: 115174.05 | E32: 125416.65 | F32: 142842.37 | G32: 170010.63
A33: Total assets / liablilities | B33: 915222.36 | C33: 996160.46 | D33: 1175625.2 | E33: 1317743.9 | F33: 1477892.9 | G33: 1611217.9
A34: Gross fixed assets | B34: 8600.13 | C34: 9788.24 | D34: 10844.38 | E34: 23969.8 | F34: 25806.09 | G34: 27614.29
A35: Total income | B35: 78211.38 | C35: 78217.13 | D35: 85030.89 | E35: 105788.58 | F35: 134866.89 | G35: 152144.97
A36: PAT net of P&E | B36: 43.54 | C36: 5323.99 | D36: 10601.71 | E36: 5707.43 | F36: 21812.57 | G36: 22181.52
A37: Trailing 4 qtrs. PAT net of P&E | B37: 43.54 | C37: 5323.99 | D37: 10601.71 | E37: 5707.43 | F37: 8131.09 | G37: 23336.79
A40: Particulars | B40: Mar-20 | C40: Mar-21 | D40: Mar-22 | E40: Mar-23 | F40: Mar-24 | G40: Mar-25
A41: PBT as % of total income | B41: 6.27 | C41: 11.26 | D41: 20.44 | E41: 15.98 | F41: 24.51 | G41: 22.57
A42: PAT as % of total income | B42: 2.08 | C42: 8.42 | D42: 15.32 | E42: 9.06 | F42: 18.43 | G42: 17.33
A43: PBPT net of P&E&OI as % of total inc net of P&E | B43: 28.11 | C43: 28.57 | D43: 29.54 | E43: 19.01 | F43: 27.94 | G43: 28.2
A44: PAT net of P&E as % of total inc net of P&E | B44: 0.06 | C44: 6.92 | D44: 12.83 | E44: 5.6 | F44: 16.55 | G44: 14.99
...

Sheet Trend_Analysis
A1: Year | B1: Revenue | C1: Rev Abs Change | D1: Rev Growth % | E1: PAT | F1: PAT Abs Change | G1: PAT Growth % | H1: Total Assets | I1: Total Debt
A2: 2020 | B2: =Table1[[#This Row],[Mar-20]] -> 78211.38 | C2: - | D2: - | E2: =Income_Statement_Data!B71 -> 1627.22 | F2: - | G2: - | H2: =Balance_Sheet_Data!B27 -> 915222.36 | I2: =Balance_Sheet_Data!B16 -> 147954.13
A3: 2021 | B3: =Income_Statement_Data!C2 -> 78217.13 | C3: =Table9[[#This Row],[Revenue]]-B2 -> 5.75 | D3: =Table9[[#This Row],[Rev Abs Change ]]/B2 -> 7.3518713e-05 | E3: =Income_Statement_Data!C71 -> 6588.5 | F3: =Table9[[#This Row],[PAT]]-E2 -> 4961.28 | G3: =Table9[[#This Row],[PAT Abs Change]]/E2 -> 3.0489301 | H3: =Balance_Sheet_Data!C27 -> 996160.46 | I3: =Balance_Sheet_Data!C16 -> 142873.16
A4: 2022 | B4: =Income_Statement_Data!D2 -> 85030.89 | C4: =Table9[[#This Row],[Revenue]]-B3 -> 6813.76 | D4: =Table9[[#This Row],[Rev Abs Change ]]/B3 -> 0.087113398 | E4: =Income_Statement_Data!D71 -> 13025.48 | F4: =Table9[[#This Row],[PAT]]-E3 -> 6436.98 | G4: =Table9[[#This Row],[PAT Abs Change]]/E3 -> 0.97700235 | H4: =Balance_Sheet_Data!D27 -> 1175625.2 | I4: =Balance_Sheet_Data!D16 -> 185133.86
A5: 2023 | B5: =Income_Statement_Data!E2 -> 105788.58 | C5: =Table9[[#This Row],[Revenue]]-B4 -> 20757.69 | D5: =Table9[[#This Row],[Rev Abs Change ]]/B4 -> 0.2441194 | E5: =Income_Statement_Data!E71 -> 9579.68 | F5: =Table9[[#This Row],[PAT]]-E4 -> -3445.8 | G5: =Table9[[#This Row],[PAT Abs Change]]/E4 -> -0.26454303 | H5: =Balance_Sheet_Data!E27 -> 1317743.9 | I5: =Balance_Sheet_Data!E16 -> 186300.05
A6: 2024 | B6: =Income_Statement_Data!F2 -> 134866.89 | C6: =Table9[[#This Row],[Revenue]]-B5 -> 29078.31 | D6: =Table9[[#This Row],[Rev Abs Change ]]/B5 -> 0.27487192 | E6: =Income_Statement_Data!F71 -> 24861.43 | F6: =Table9[[#This Row],[PAT]]-E5 -> 15281.75 | G6: =Table9[[#This Row],[PAT Abs Change]]/E5 -> 1.5952255 | H6: =Balance_Sheet_Data!F27 -> 1477892.9 | I6: =Balance_Sheet_Data!F16 -> 196811.75
A7: 2025 | B7: =Income_Statement_Data!G2 -> 152144.97 | C7: =Table9[[#This Row],[Revenue]]-B6 -> 17278.08 | D7: =Table9[[#This Row],[Rev Abs Change ]]/B6 -> 0.1281121 | E7: =Income_Statement_Data!G71 -> 26373.48 | F7: =Table9[[#This Row],[PAT]]-E6 -> 1512.05 | G7: =Table9[[#This Row],[PAT Abs Change]]/E6 -> 0.060819108 | H7: =Balance_Sheet_Data!G27 -> 1611217.9 | I7: =Balance_Sheet_Data!G16 -> 184146.51
B26: Revenue shows steady growth, especially strong after 2022 | H26: Total assets increase consistently over all years
B27: Indicates expansion in operations and improved business performance | H27: Shows continuous expansion and growth in company size
B48: PAT shows overall growth but drops in 2023 | H48: Debt shows moderate fluctuation but no sharp increase
B49: Indicates temporary profitability pressure, followed by strong recovery | H49: Indicates controlled borrowing and stable financial risk

Sheet TVM_Analysis
A1: Dividend Data | D1: Dividend Discount Model (DDM) | G1: Present value of dividend stream
A2: Year | B2: Dividend | D2: Item | E2: Value | G2: Year | H2: Dividend | I2: PV Factor | J2: Present Value
A3: 2022 | B3: =Market_Data!C6 -> 1 | D3: Growth Rate (g) | E3: =(B4/B3)^(0.2)-1 -> 0 | G3: 2022 | H3: =Market_Data!C6 -> 1 | I3: =1/(1+0.12)^1 -> 0.89285714 | J3: =H3*I3 -> 0.89285714
A4: 2023 | B4: =Market_Data!C5 -> 1 | D4: Next Dividend (D1) | E4: {=B6*E6(1+E3)} -> #REF! | G4: 2023 | H4: =Market_Data!C5 -> 1 | I4: =1/(1+0.12)^2 -> 0.79719388 | J4: =H4*I4 -> 0.79719388
A5: 2024 | B5: =Table8[[#This Row],[Dividend per share]] -> 1 | D5: Cost of Equity (Ke) | E5: 0.12 | G5: 2024 | H5: =Table8[[#This Row],[Dividend per share]] -> 1 | I5: =1/(1+0.12)^3 -> 0.71178025 | J5: =H5*I5 -> 0.71178025
A6: 2025 | B6: =Market_Data!C3 -> 1 | D6: Intrinsic Value | E6: =E4/(E5-E3) -> #REF! | G6: 2025 | H6: =Market_Data!C3 -> 1 | I6: =1/(1+0.12)^4 -> 0.63551808 | J6: =H6*I6 -> 0.63551808
I7: Total PV of Dividend | J7: =SUM(Table15[Present Value]) -> 3.0373493
D8: Ke Assume | E8: 0.12
D10: Dividend Discount Model shows low intrinsic value due to low dividend payout
D11: Hence, DDM is less suitable for growth banks like Axis Bank

Sheet WACC_Analysis
A1: Item | B1: Value
A2: Total Debt (D) | B2: =Balance_Sheet_Data!G16 -> 184146.51 | E2: Cost of Debt is adjusted to 7% as banking interest includes deposits and may distort actual borrowing cost.
A3: Total Equity (E) | B3: =Balance_Sheet_Data!G107 -> 179725.12 | E3: The calculated WACC of 9% indicates a relatively low cost of capital.
A4: Total Value (V = D+E) | B4: =B2+B3 -> 363871.63 | E4: This suggests that the company can raise funds efficiently at a lower cost.
A5: Cost of Debt (Kd) | B5: =Income_Statement_Data!G30/B2 -> 0.371059 | E5: Lower WACC improves investment attractiveness and supports growth opportunities.
A6: Cost of Debt (Kd) | B6: 0.07 | C6: Assume
A7: Cost of Equity (Ke) | B7: 0.12 | C7: Assume
A8: Tax Rate (T) | B8: =Income_Statement_Data!G54/Income_Statement_Data!G61 -> 0.17989143
A9: WACC | B9: =(B3/B4*B7)+B2/B4*B6*(1-B8) -> 0.088323521
A11: WACC = (E/V × Ke) + (D/V × Kd × (1 - T))

Sheet Capital_Budgeting_Analysis
A1: Year | B1: Cash Flow | C1: Present _Value_Factor 1/ (1+r)^t] | D1: PV | E1: Cumulative Cash Flow
A2: 0 | B2: -10000 | C2: =1/(1+$I$6)^Table18[[#This Row],[Year]] -> 1 | D2: =Table18[[#This Row],[Cash Flow]]*Table18[[#This Row],[Present _Value_Factor 1/ (1+r)^t']]] -> -10000 | E2: =Table18[[#This Row],[PV]] -> -10000 | G2: Assume Project
A3: 1 | B3: 2500 | C3: =1/(1+$I$6)^Table18[[#This Row],[Year]] -> 0.91884443 | D3: =Table18[[#This Row],[Cash Flow]]*Table18[[#This Row],[Present _Value_Factor 1/ (1+r)^t']]] -> 2297.1111 | E3: =E2+Table18[[#This Row],[PV]] -> -7702.8889 | G3: Initial Investment = ₹10,000 Cr
A4: 2 | B4: 3000 | C4: =1/(1+$I$6)^Table18[[#This Row],[Year]] -> 0.84427508 | D4: =Table18[[#This Row],[Cash Flow]]*Table18[[#This Row],[Present _Value_Factor 1/ (1+r)^t']]] -> 2532.8252 | E4: =E3+Table18[[#This Row],[PV]] -> -5170.0637 | G4: Project Life = 5 years
A5: 3 | B5: 3500 | C5: =1/(1+$I$6)^Table18[[#This Row],[Year]] -> 0.77575745 | D5: =Table18[[#This Row],[Cash Flow]]*Table18[[#This Row],[Present _Value_Factor 1/ (1+r)^t']]] -> 2715.1511 | E5: =E4+Table18[[#This Row],[PV]] -> -2454.9126 | G5: Growth = based on revenue trend
A6: 4 | B6: 4000 | C6: =1/(1+$I$6)^Table18[[#This Row],[Year]] -> 0.71280041 | D6: =Table18[[#This Row],[Cash Flow]]*Table18[[#This Row],[Present _Value_Factor 1/ (1+r)^t']]] -> 2851.2016 | E6: =Table18[[#This Row],[PV]] -> 2851.2016 | G6: Discount rate ( WACC) | I6: =WACC_Analysis!B9 -> 0.088323521
A7: 5 | B7: 4500 | C7: =1/(1+$I$6)^Table18[[#This Row],[Year]] -> 0.65495268 | D7: =Table18[[#This Row],[Cash Flow]]*Table18[[#This Row],[Present _Value_Factor 1/ (1+r)^t']]] -> 2947.2871 | E7: =E6+Table18[[#This Row],[PV]] -> 5798.4887
C8: IRR | D8: =IRR(Table18[Cash Flow]) -> 0.19711108
C9: NPV | D9: =SUM(Table18[PV]) -> 3343.7732
B12: The Net Present Value (NPV) is positive, indicating that the project is expected to generate value.
B13: The Internal Rate of Return (IRR) of 20% is significantly higher than the WACC of 9%.
B14: This shows that the project's return exceeds the required return.
B15: Hence, the investment is financially viable and should be accepted.

Sheet Capital_Structure_Analysis
A1: Year | B1: Total Debt | C1: Total Equity | D1: Total Capital | E1: Debt % | F1: Equity %
A2: 2020 | B2: =Balance_Sheet_Data!B114 -> 147954.13 | C2: =Balance_Sheet_Data!B107 -> 84947.84 | D2: =Table22[[#This Row],[Total Debt]]+Table22[[#This Row],[Total Equity]] -> 232901.97 | E2: =Table22[[#This Row],[Total Debt]]/Table22[[#This Row],[Total Capital]] -> 0.63526354 | F2: =Table22[[#This Row],[Total Equity]]/Table22[[#This Row],[Total Capital]] -> 0.36473646
A3: 2021 | B3: =Balance_Sheet_Data!C114 -> 142873.16 | C3: =Balance_Sheet_Data!C107 -> 101603.01 | D3: =Table22[[#This Row],[Total Debt]]+Table22[[#This Row],[Total Equity]] -> 244476.17 | E3: =Table22[[#This Row],[Total Debt]]/Table22[[#This Row],[Total Capital]] -> 0.58440526 | F3: =Table22[[#This Row],[Total Equity]]/Table22[[#This Row],[Total Capital]] -> 0.41559474
A4: 2022 | B4: =Balance_Sheet_Data!D114 -> 185133.86 | C4: =Balance_Sheet_Data!D107 -> 115174.06 | D4: =Table22[[#This Row],[Total Debt]]+Table22[[#This Row],[Total Equity]] -> 300307.92 | E4: =Table22[[#This Row],[Total Debt]]/Table22[[#This Row],[Total Capital]] -> 0.61648011 | F4: =Table22[[#This Row],[Total Equity]]/Table22[[#This Row],[Total Capital]] -> 0.38351989
A5: 2023 | B5: =Balance_Sheet_Data!E114 -> 186300.05 | C5: =Balance_Sheet_Data!E107 -> 125416.65 | D5: =Table22[[#This Row],[Total Debt]]+Table22[[#This Row],[Total Equity]] -> 311716.7 | E5: =Table22[[#This Row],[Total Debt]]/Table22[[#This Row],[Total Capital]] -> 0.59765823 | F5: =Table22[[#This Row],[Total Equity]]/Table22[[#This Row],[Total Capital]] -> 0.40234177
A6: 2024 | B6: =Balance_Sheet_Data!F114 -> 196811.75 | C6: =Balance_Sheet_Data!F107 -> 151061.58 | D6: =Table22[[#This Row],[Total Debt]]+Table22[[#This Row],[Total Equity]] -> 347873.33 | E6: =Table22[[#This Row],[Total Debt]]/Table22[[#This Row],[Total Capital]] -> 0.56575694 | F6: =Table22[[#This Row],[Total Equity]]/Table22[[#This Row],[Total Capital]] -> 0.43424306
A7: 2025 | B7: =Balance_Sheet_Data!G114 -> 184146.51 | C7: =Balance_Sheet_Data!G107 -> 179725.12 | D7: =Table22[[#This Row],[Total Debt]]+Table22[[#This Row],[Total Equity]] -> 363871.63 | E7: =Table22[[#This Row],[Total Debt]]/Table22[[#This Row],[Total Capital]] -> 0.50607548 | F7: =Table22[[#This Row],[Total Equity]]/Table22[[#This Row],[Total Capital]] -> 0.49392452
A10: The capital structure shows a gradual decrease in debt proportion from 64% to 51%
A11: Equity contribution has increased steadily, indicating strengthening financial position
A12: The company is reducing dependency on debt and improving stability
A13: As a bank, higher debt is normal, but the trend reflects improved capital adequacy

Sheet Leverage_Analysis
A1: Year | B1: Revenue | C1: EBIT | D1: % Change in Revenue | E1: % Chnage in EBIT | F1: Interest | G1: DOL | H1: DFL | I1: Interest Coverage
A2: 2020 | B2: {=TRANSPOSE(Table1[[#This Row],[Mar-20]:[Mar-25]])} -> 78211.38 | C2: {=TRANSPOSE(Income_Statement_Data!B61:G61)} -> 21461.05 | F2: {=TRANSPOSE(Income_Statement_Data!B30:G30)} -> 37428.96 | H2: =C2/(C2-F2) -> -1.3440112 | I2: =C2/F2 -> 0.57338088
A3: 2021 | B3: 78217.13 | C3: 21893.96 | D3: =(B3-B2)/B2 -> 7.3518713e-05 | E3: =(C3-C2)/C2 -> 0.020171893 | F3: 34107.11 | H3: =C3/(C3-F3) -> -1.7926546 | I3: =C3/F3 -> 0.64191777
A4: 2022 | B4: 85030.89 | C4: 24258.82 | D4: =(B4-B3)/B3 -> 0.087113398 | E4: =(C4-C3)/C3 -> 0.10801427 | F4: 34244.61 | G4: =E4/D4 -> 1.2399271 | H4: =C4/(C4-F4) -> -2.4293341 | I4: =C4/F4 -> 0.7083982
A5: 2023 | B5: 105788.58 | C5: 19278.16 | D5: =(B5-B4)/B4 -> 0.2441194 | E5: =(C5-C4)/C4 -> -0.20531337 | F5: 42218.02 | G5: =E5/D5 -> -0.84103666 | H5: =C5/(C5-F5) -> -0.84037828 | I5: =C5/F5 -> 0.45663345
A6: 2024 | B6: 134866.89 | C6: 36710.45 | D6: =(B6-B5)/B5 -> 0.27487192 | E6: =(C6-C5)/C5 -> 0.90425072 | F6: 59474.16 | G6: =E6/D6 -> 3.2897166 | H6: =C6/(C6-F6) -> -1.6126743 | I6: =C6/F6 -> 0.61725042
A7: 2025 | B7: 152144.97 | C7: 41565.07 | D7: =(B7-B6)/B6 -> 0.1281121 | E7: =(C7-C6)/C6 -> 0.13224082 | F7: 68329.22 | G7: =E7/D7 -> 1.0322274 | H7: =C7/(C7-F7) -> -1.5530129 | I7: =C7/F7 -> 0.60830593
H9: Negative DFL indicates EBIT is lower than interest expense in some years
H10: This reflects the nature of banking business where interest is a core cost
H11: Hence, interpretation should consider industry context

Sheet Ratio_Analysis
A1: Year | B1: Revenue | C1: PAT | D1: Shareholders Funds | E1: Total Assets | F1: ROE | G1: ROA | H1: Net Profit Margin | I1: Asset Turnover
A2: 2020 | B2: {=TRANSPOSE(Table1[[#This Row],[Mar-20]:[Mar-25]])} -> 78211.38 | C2: {=TRANSPOSE(Ratios_Data!B36:G36)} -> 43.54 | D2: {=TRANSPOSE(Balance_Sheet_Data!B107:G107)} -> 84947.84 | E2: {=TRANSPOSE(Balance_Sheet_Data!B74:G74)} -> 915222.36 | F2: =C2/D2 -> 0.00051254982 | G2: =C2/E2 -> 4.7573138e-05 | H2: =C2/B2 -> 0.00055669648 | I2: =B2/E2 -> 0.085456151
A3: 2021 | B3: 78217.13 | C3: 5323.99 | D3: 101603.01 | E3: 996160.46 | F3: =C3/D3 -> 0.052399924 | G3: =C3/E3 -> 0.0053445105 | H3: =C3/B3 -> 0.068066803 | I3: =B3/E3 -> 0.078518605
A4: 2022 | B4: 85030.89 | C4: 10601.71 | D4: 115174.06 | E4: 1175625.2 | F4: =C4/D4 -> 0.09204946 | G4: =C4/E4 -> 0.0090179333 | H4: =C4/B4 -> 0.12468069 | I4: =B4/E4 -> 0.072328228
A5: 2023 | B5: 105788.58 | C5: 5707.43 | D5: 125416.65 | E5: 1317743.9 | F5: =C5/D5 -> 0.045507754 | G5: =C5/E5 -> 0.0043312135 | H5: =C5/B5 -> 0.053951287 | I5: =B5/E5 -> 0.080280079
A6: 2024 | B6: 134866.89 | C6: 21812.57 | D6: 151061.58 | E6: 1477892.9 | F6: =C6/D6 -> 0.14439522 | G6: =C6/E6 -> 0.014759236 | H6: =C6/B6 -> 0.16173406 | I6: =B6/E6 -> 0.0912562
A7: 2025 | B7: 152144.97 | C7: 22181.52 | D7: 179725.12 | E7: 1611217.9 | F7: =C7/D7 -> 0.12341914 | G7: =C7/E7 -> 0.013766927 | H7: =C7/B7 -> 0.145792 | I7: =B7/E7 -> 0.094428549
A9: The company shows improving profitability with increasing ROE over the years
A10: ROA remains low but stable, which is typical for banking institutions
A11: Net profit margin has improved significantly, indicating better cost efficiency
A12: Asset turnover remains consistent, reflecting stable utilisation of assets
A13: Overall, Axis Bank demonstrates strong financial performance and improving efficiency

Sheet Dividend_Policy_Analysis
A1: Year | B1: Dividend per Share | C1: EPS | D1: Payout Ratio | E1: Retention Ratio
A2: 2020 | C2: {=TRANSPOSE(Ratios_Data!B11:G11)} -> 0.15
A3: 2021 | C3: 17.38
A4: 2022 | B4: =Market_Data!C6 -> 1 | C4: 34.54 | D4: =B4/C4 -> 0.02895194 | E4: =1-D4 -> 0.97104806
A5: 2023 | B5: =Table8[[#This Row],[Dividend per share]] -> 1 | C5: 18.55 | D5: =B5/C5 -> 0.053908356 | E5: =1-D5 -> 0.94609164
A6: 2024 | B6: =Market_Data!C4 -> 1 | C6: 26.34 | D6: =B6/C6 -> 0.037965072 | E6: =1-D6 -> 0.96203493
A7: 2025 | B7: =Market_Data!C3 -> 1 | C7: 75.34 | D7: =B7/C7 -> 0.013273162 | E7: =1-D7 -> 0.98672684
B10: No dividend in 2020–2021 indicates capital conservation
B11: From 2022 onward, stable dividend of ₹1 introduced
B12: Payout ratio remains very low (2–7%)
B13: High retention (93–98%) shows growth focus
B14: Dividend policy is conservative but sustainable

Sheet Final_Conclusion
